Workbook

Sheet Post Estival
A1: Local | B1: Usuario | C1: Patente | D1: Status | E1: Observacion | F1: Telemetria
A2: 120 | B2: HDVSHKSV64 | C2: =RIGHT(B2,6) -> HKSV64 | D2: 🔴 | F2: =VLOOKUP(B2,Telemetria!B$2:E$98,3,0) -> Instalacion Lista
A3: 120 | B3: HDVSHZRX80 | C3: =RIGHT(B3,6) -> HZRX80 | D3: 🟢 | F3: =VLOOKUP(B3,Telemetria!B$2:E$98,3,0) -> Instalacion Lista
A4: 120 | B4: HDVSKCHJ51 | C4: =RIGHT(B4,6) -> KCHJ51 | D4: 🟢 | F4: =VLOOKUP(B4,Telemetria!B$2:E$98,3,0) -> Instalacion Lista
A5: 120 | B5: HDVSKJJX80 | C5: =RIGHT(B5,6) -> KJJX80 | D5: 🟢 | E5: Revisar | F5: =VLOOKUP(B5,Telemetria!B$2:E$98,3,0) -> Instalacion Lista
A6: 120 | B6: HDVSKKJZ64 | C6: =RIGHT(B6,6) -> KKJZ64 | D6: 🟢 | F6: =VLOOKUP(B6,Telemetria!B$2:E$98,3,0) -> Instalacion Lista
A7: 120 | B7: HDVSKTZY10 | C7: =RIGHT(B7,6) -> KTZY10 | D7: 🟡 | F7: =VLOOKUP(B7,Telemetria!B$2:E$98,3,0) -> Instalacion Lista
A8: 120 | B8: HDVSKTZY11 | C8: =RIGHT(B8,6) -> KTZY11 | D8: 🟢 | F8: =VLOOKUP(B8,Telemetria!B$2:E$98,3,0) -> Pendiente Instalacion
A9: 120 | B9: HDVSKYSJ80 | C9: =RIGHT(B9,6) -> KYSJ80 | D9: 🟢 | F9: =VLOOKUP(B9,Telemetria!B$2:E$98,3,0) -> Instalacion Lista
A10: 120 | B10: HDVSKZZY17 | C10: =RIGHT(B10,6) -> KZZY17 | D10: 🟢 | F10: =VLOOKUP(B10,Telemetria!B$2:E$98,3,0) -> Instalacion Lista
A11: 120 | B11: HDVSPGJL89 | C11: =RIGHT(B11,6) -> PGJL89 | D11: 🟢 | F11: =VLOOKUP(B11,Telemetria!B$2:E$98,3,0) -> Instalacion Lista
A12: 120 | B12: HDVSLFZC21 | C12: =RIGHT(B12,6) -> LFZC21 | D12: 🟡 | F12: =VLOOKUP(B12,Telemetria!B$2:E$98,3,0) -> Instalacion Lista
A13: 120 | B13: HDVSLHVR22 | C13: =RIGHT(B13,6) -> LHVR22 | D13: 🟢 | F13: =VLOOKUP(B13,Telemetria!B$2:E$98,3,0) -> Instalacion Lista
A14: 120 | B14: HDVSRGVV55 | C14: =RIGHT(B14,6) -> RGVV55 | D14: 🔴 | F14: =VLOOKUP(B14,Telemetria!B$2:E$98,3,0) -> Instalacion Lista
A15: 120 | B15: HDVSRXTL44 | C15: =RIGHT(B15,6) -> RXTL44 | D15: 🔴 | F15: =VLOOKUP(B15,Telemetria!B$2:E$98,3,0) -> Instalacion Lista
A16: 120 | B16: HDVSRYJR47 | C16: =RIGHT(B16,6) -> RYJR47 | D16: 🟢 | F16: =VLOOKUP(B16,Telemetria!B$2:E$98,3,0) -> Instalacion Lista
A17: 120 | B17: HDVSTKWX57 | C17: =RIGHT(B17,6) -> TKWX57 | D17: 🔴 | F17: =VLOOKUP(B17,Telemetria!B$2:E$98,3,0) -> Instalacion Lista
A18: 120 | B18: HDVSTRYL82 | C18: =RIGHT(B18,6) -> TRYL82 | D18: 🟡 | E18: Sacar | F18: =VLOOKUP(B18,Telemetria!B$2:E$98,3,0) -> Instalacion Lista
A19: 120 | B19: HDVSTSCT51 | C19: =RIGHT(B19,6) -> TSCT51 | D19: 🔴 | E19: Sacar | F19: =VLOOKUP(B19,Telemetria!B$2:E$98,3,0) -> Instalacion Lista
A20: 120 | B20: HDVSTZCH26 | C20: =RIGHT(B20,6) -> TZCH26 | D20: 🟢 | F20: =VLOOKUP(B20,Telemetria!B$2:E$98,3,0) -> Instalacion Lista
A21: 121 | B21: HDVSCJJY36 | C21: =RIGHT(B21,6) -> CJJY36 | D21: 🟢 | E21: Sigue | F21: =VLOOKUP(B21,Telemetria!B$2:E$98,3,0) -> Instalacion Lista
A22: 121 | B22: HDVSRHXG50 | C22: =RIGHT(B22,6) -> RHXG50 | D22: 🟢 | E22: Sigue | F22: =VLOOKUP(B22,Telemetria!B$2:E$98,3,0) -> Instalacion Lista | G22: en panne
A23: 121 | B23: HDVSVLHB59 | C23: =RIGHT(B23,6) -> VLHB59 | D23: 🟢 | E23: Sigue | F23: =VLOOKUP(B23,Telemetria!B$2:E$98,3,0) -> Instalacion Lista
A24: 121 | B24: HDVSRHWY99 | C24: =RIGHT(B24,6) -> RHWY99 | D24: 🟢 | E24: Sigue | F24: =VLOOKUP(B24,Telemetria!B$2:E$98,3,0) -> Instalacion Lista
A25: 121 | B25: HDVSPTGD93 | C25: =RIGHT(B25,6) -> PTGD93 | D25: 🟢 | E25: Sigue | F25: =VLOOKUP(B25,Telemetria!B$2:E$98,3,0) -> Instalacion Lista
A26: 121 | B26: HDVSRPGK29 | C26: =RIGHT(B26,6) -> RPGK29 | D26: 🟢 | E26: Sigue | F26: =VLOOKUP(B26,Telemetria!B$2:E$98,3,0) -> Instalacion Lista | G26: en panne
A27: 121 | B27: HDVSSBTV68 | C27: =RIGHT(B27,6) -> SBTV68 | D27: 🟢 | E27: Sigue | F27: =VLOOKUP(B27,Telemetria!B$2:E$98,3,0) -> Instalacion Lista
A28: 121 | B28: HDVSPSLP82 | C28: =RIGHT(B28,6) -> SLP82 | D28: 🟢 | E28: Sigue | F28: =VLOOKUP(B28,Telemetria!B$2:E$98,3,0) -> #N/A
A29: 121 | B29: HDVSVDZC94 | C29: =RIGHT(B29,6) -> VDZC94 | D29: 🟢 | E29: Sigue | F29: =VLOOKUP(B29,Telemetria!B$2:E$98,3,0) -> Instalacion Lista
A30: 121 | B30: HDVSTYWH80 | C30: =RIGHT(B30,6) -> TYWH80 | D30: 🟢 | E30: Sigue | F30: =VLOOKUP(B30,Telemetria!B$2:E$98,3,0) -> Instalacion Lista
A31: 121 | B31: HDVSRVPT55 | C31: =RIGHT(B31,6) -> RVPT55 | D31: 🟢 | E31: Sigue | F31: =VLOOKUP(B31,Telemetria!B$2:E$98,3,0) -> Pendiente Instalacion | G31: en panne
A32: 58 | B32: HDVSCJYL78 | C32: =RIGHT(B32,6) -> CJYL78 | D32: 🟡 | E32: No tenia | F32: =VLOOKUP(B32,Telemetria!B$2:E$98,3,0) -> Pendiente Instalacion
A33: 58 | B33: HDVSDLCB16 | C33: =RIGHT(B33,6) -> DLCB16 | D33: 🟢 | F33: =VLOOKUP(B33,Telemetria!B$2:E$98,3,0) -> Instalacion Lista
A34: 58 | B34: HDVSJPVT35 | C34: =RIGHT(B34,6) -> JPVT35 | D34: 🟡 | E34: Retirar 10/03 | F34: =VLOOKUP(B34,Telemetria!B$2:E$98,3,0) -> Instalacion Lista
A35: 58 | B35: HDVSLFTL60 | C35: =RIGHT(B35,6) -> LFTL60 | D35: 🔴 | E35: 16 PROVIDENCIA 10:30 | F35: =VLOOKUP(B35,Telemetria!B$2:E$98,3,0) -> Instalacion Lista
A36: 58 | B36: HDVSPKPT90 | C36: =RIGHT(B36,6) -> PKPT90 | D36: 🔴 | E36: 17 PROVIDENCIA 15:00 | F36: =VLOOKUP(B36,Telemetria!B$2:E$98,3,0) -> Instalacion Lista
A37: 58 | B37: HDVSPPWY63 | C37: =RIGHT(B37,6) -> PPWY63 | D37: 🟢 | F37: =VLOOKUP(B37,Telemetria!B$2:E$98,3,0) -> Instalacion Lista
A38: 58 | B38: HDVSPSCW71 | C38: =RIGHT(B38,6) -> PSCW71 | D38: 🔴 | E38: 17 PROVIDENCIA 15:30 | F38: =VLOOKUP(B38,Telemetria!B$2:E$98,3,0) -> Instalacion Lista
A39: 58 | B39: HDVSRDPF14 | C39: =RIGHT(B39,6) -> RDPF14 | D39: 🟡 | E39: No tenia | F39: =VLOOKUP(B39,Telemetria!B$2:E$98,3,0) -> Pendiente Instalacion
A40: 58 | B40: HDVSSFJT82 | C40: =RIGHT(B40,6) -> SFJT82 | D40: 🔴 | E40: Retirar 10/03 | F40: =VLOOKUP(B40,Telemetria!B$2:E$98,3,0) -> Instalacion Lista
...

Sheet Mapeo de flota
A1: Local | B1: Identificador | C1: Patente | D1: Status | E1: Teletria | F1: branding Si/No | G1: Resolucion sanitaria | H1: Formulario | I1: Branding (Estado) | J1: Lamas | K1: Separador | L1: Palet en piso | M1: Permiso SAC
A2: L120 (Temuco) | B2: HDVSHZRX80 | C2: =RIGHT(B2,6) -> HZRX80 | D2: Activa | E2: =VLOOKUP(C2,Telemetria!C$1:E$99,2,0) -> Instalacion Lista | F2: Si | G2: =VLOOKUP(C2,'Hoja 27'!C$1:E$63,3,0) -> Si cuenta con RS | H2: =VLOOKUP(C2,'Hoja 33'!B$2:E$67,1,0) -> #REF! | I2: ✅ | J2: ✅ | K2: ✅ | M2: ❌
A3: L120 (Temuco) | B3: HDVSKCHJ51 | C3: =RIGHT(B3,6) -> KCHJ51 | D3: Activa | E3: =VLOOKUP(C3,Telemetria!C$1:E$99,2,0) -> Instalacion Lista | F3: Si | G3: =VLOOKUP(C3,'Hoja 27'!C$1:E$63,3,0) -> Si cuenta con RS | H3: =VLOOKUP(C3,'Hoja 33'!B$2:E$67,1,0) -> #REF! | I3: ✅ | J3: ✅ | K3: ✅ | M3: ❌
A4: L120 (Temuco) | B4: HDVSKKJZ64 | C4: =RIGHT(B4,6) -> KKJZ64 | D4: Activa | E4: =VLOOKUP(C4,Telemetria!C$1:E$99,2,0) -> Instalacion Lista | F4: Si | G4: =VLOOKUP(C4,'Hoja 27'!C$1:E$63,3,0) -> Si cuenta con RS | H4: =VLOOKUP(C4,'Hoja 33'!B$2:E$67,1,0) -> #REF! | I4: ✅ | J4: ✅ | K4: ✅ | M4: ❌
A5: L120 (Temuco) | B5: HDVSKYSJ80 | C5: =RIGHT(B5,6) -> KYSJ80 | D5: Activa | E5: =VLOOKUP(C5,Telemetria!C$1:E$99,2,0) -> Instalacion Lista | F5: Si | G5: =VLOOKUP(C5,'Hoja 27'!C$1:E$63,3,0) -> Si cuenta con RS | H5: =VLOOKUP(C5,'Hoja 33'!B$2:E$67,1,0) -> #REF! | I5: ✅ | J5: ✅ | K5: ✅ | M5: ❌
A6: L120 (Temuco) | B6: HDVSKZZY17 | C6: =RIGHT(B6,6) -> KZZY17 | D6: Activa | E6: =VLOOKUP(C6,Telemetria!C$1:E$99,2,0) -> Instalacion Lista | F6: Si | G6: =VLOOKUP(C6,'Hoja 27'!C$1:E$63,3,0) -> Si cuenta con RS | H6: =VLOOKUP(C6,'Hoja 33'!B$2:E$67,1,0) -> #REF! | I6: ✅ | J6: ✅ | K6: ✅ | M6: ❌
A7: L120 (Temuco) | B7: HDVSLHVR22 | C7: =RIGHT(B7,6) -> LHVR22 | D7: Activa | E7: =VLOOKUP(C7,Telemetria!C$1:E$99,2,0) -> Instalacion Lista | F7: Si | G7: =VLOOKUP(C7,'Hoja 27'!C$1:E$63,3,0) -> Si cuenta con RS | H7: =VLOOKUP(C7,'Hoja 33'!B$2:E$67,1,0) -> #REF! | I7: Pendiente | J7: Pendiente | K7: Pendiente | M7: ❌ | N7: En panne
A8: L120 (Temuco) | B8: HDVSPGJL89 | C8: =RIGHT(B8,6) -> PGJL89 | D8: Activa | E8: =VLOOKUP(C8,Telemetria!C$1:E$99,2,0) -> Instalacion Lista | F8: Si | G8: =VLOOKUP(C8,'Hoja 27'!C$1:E$63,3,0) -> Si cuenta con RS | H8: =VLOOKUP(C8,'Hoja 33'!B$2:E$67,1,0) -> #REF! | I8: ✅ | J8: ✅ | K8: ✅ | M8: ❌ | N8: Coordinar instalacion
A9: L120 (Temuco) | B9: HDVSRXTL44 | C9: =RIGHT(B9,6) -> RXTL44 | D9: Activa | E9: =VLOOKUP(C9,Telemetria!C$1:E$99,2,0) -> Instalacion Lista | F9: Si | G9: =VLOOKUP(C9,'Hoja 27'!C$1:E$63,3,0) -> Si cuenta con RS | H9: =VLOOKUP(C9,'Hoja 33'!B$2:E$67,1,0) -> #REF! | I9: ✅ | J9: ✅ | K9: ✅ | M9: ❌
A10: L120 (Temuco) | B10: HDVSRYJR47 | C10: =RIGHT(B10,6) -> RYJR47 | D10: Activa | E10: =VLOOKUP(C10,Telemetria!C$1:E$99,2,0) -> Instalacion Lista | F10: Si | G10: =VLOOKUP(C10,'Hoja 27'!C$1:E$63,3,0) -> Si cuenta con RS | H10: =VLOOKUP(C10,'Hoja 33'!B$2:E$67,1,0) -> #REF! | I10: ✅ | J10: ✅ | K10: ✅ | M10: ❌ | N10: FAILA UNA LAMA
A11: L120 (Temuco) | B11: HDVSTKWX57 | C11: =RIGHT(B11,6) -> TKWX57 | D11: Activa | E11: =VLOOKUP(C11,Telemetria!C$1:E$99,2,0) -> Instalacion Lista | F11: Si | G11: =VLOOKUP(C11,'Hoja 27'!C$1:E$63,3,0) -> No se encuentra resolución sanitaria | H11: =VLOOKUP(C11,'Hoja 33'!B$2:E$67,1,0) -> #REF! | I11: ✅ | J11: ✅ | K11: ✅ | M11: ❌
A12: L120 (Temuco) | B12: HDVSTRYL82 | C12: =RIGHT(B12,6) -> TRYL82 | D12: Activa | E12: =VLOOKUP(C12,Telemetria!C$1:E$99,2,0) -> Instalacion Lista | F12: Si | G12: =VLOOKUP(C12,'Hoja 27'!C$1:E$63,3,0) -> No se encuentra documentación | H12: =VLOOKUP(C12,'Hoja 33'!B$2:E$67,1,0) -> #REF! | I12: ✅ | J12: ✅ | K12: ✅ | M12: ❌
A13: L120 (Temuco) | B13: HDVSTSCT51 | C13: =RIGHT(B13,6) -> TSCT51 | D13: Activa | E13: =VLOOKUP(C13,Telemetria!C$1:E$99,2,0) -> Instalacion Lista | F13: Si | G13: =VLOOKUP(C13,'Hoja 27'!C$1:E$63,3,0) -> No se encuentra documentación | H13: =VLOOKUP(C13,'Hoja 33'!B$2:E$67,1,0) -> #REF! | I13: ✅ | J13: ✅ | K13: ✅ | M13: ❌
A14: L120 (Temuco) | B14: HDVSTZCH26 | C14: =RIGHT(B14,6) -> TZCH26 | D14: Activa | E14: =VLOOKUP(C14,Telemetria!C$1:E$99,2,0) -> Instalacion Lista | F14: Si | G14: =VLOOKUP(C14,'Hoja 27'!C$1:E$63,3,0) -> Si cuenta con RS | H14: =VLOOKUP(C14,'Hoja 33'!B$2:E$67,1,0) -> #REF! | I14: ✅ | J14: ✅ | K14: ✅ | M14: ❌
A15: 121 (Punta Arenas) | B15: HDVSCJJY36 | C15: =RIGHT(B15,6) -> CJJY36 | D15: Activa | E15: =VLOOKUP(C15,Telemetria!C$1:E$99,2,0) -> Instalacion Lista | F15: Si | G15: =VLOOKUP(C15,'Hoja 27'!C$1:E$63,3,0) -> Si cuenta con RS | H15: =VLOOKUP(C15,'Hoja 33'!B$2:E$67,1,0) -> #REF! | I15: Pendiente | J15: Pendiente | K15: Pendiente | M15: ❌
A16: 121 (Punta Arenas) | B16: HDVSPSLP82 | C16: =RIGHT(B16,6) -> PSLP82 | D16: Activa | E16: =VLOOKUP(C16,Telemetria!C$1:E$99,2,0) -> Instalacion Lista | F16: Si | G16: =VLOOKUP(C16,'Hoja 27'!C$1:E$63,3,0) -> No se encuentra resolución sanitaria | H16: =VLOOKUP(C16,'Hoja 33'!B$2:E$67,1,0) -> #REF! | I16: ✅ | J16: ✅ | K16: ❌ | M16: ❌
A17: 121 (Punta Arenas) | B17: HDVSPTGD93 | C17: =RIGHT(B17,6) -> PTGD93 | D17: Activa | E17: =VLOOKUP(C17,Telemetria!C$1:E$99,2,0) -> Instalacion Lista | F17: Si | G17: =VLOOKUP(C17,'Hoja 27'!C$1:E$63,3,0) -> Si cuenta con RS | H17: =VLOOKUP(C17,'Hoja 33'!B$2:E$67,1,0) -> #REF! | I17: ✅ | J17: ✅ | K17: ✅ | M17: ❌
A18: 121 (Punta Arenas) | B18: HDVSRHWY99 | C18: =RIGHT(B18,6) -> RHWY99 | D18: Panne | E18: =VLOOKUP(C18,Telemetria!C$1:E$99,2,0) -> Instalacion Lista | F18: Si | G18: =VLOOKUP(C18,'Hoja 27'!C$1:E$63,3,0) -> Si cuenta con RS | H18: =VLOOKUP(C18,'Hoja 33'!B$2:E$67,1,0) -> #REF! | I18: ❌ | J18: ✅ | K18: ✅ | M18: ❌
A19: 121 (Punta Arenas) | B19: HDVSRVPT55 | C19: =RIGHT(B19,6) -> RVPT55 | D19: Inactiva | E19: =VLOOKUP(C19,Telemetria!C$1:E$99,2,0) -> Pendiente Instalacion | F19: Si | G19: =VLOOKUP(C19,'Hoja 27'!C$1:E$63,3,0) -> Si cuenta con RS | H19: =VLOOKUP(C19,'Hoja 33'!B$2:E$67,1,0) -> #REF! | I19: ✅ | J19: ✅ | K19: ✅ | M19: ❌ | N19: Coordinar instalacion
A20: 121 (Punta Arenas) | B20: HDVSSBTV68 | C20: =RIGHT(B20,6) -> SBTV68 | D20: Activa | E20: =VLOOKUP(C20,Telemetria!C$1:E$99,2,0) -> Instalacion Lista | F20: Si | G20: =VLOOKUP(C20,'Hoja 27'!C$1:E$63,3,0) -> Si cuenta con RS | H20: =VLOOKUP(C20,'Hoja 33'!B$2:E$67,1,0) -> #REF! | I20: ✅ | J20: ✅ | K20: ✅ | M20: ❌
A21: 121 (Punta Arenas) | B21: HDVSTYWH80 | C21: =RIGHT(B21,6) -> TYWH80 | D21: Activa | E21: =VLOOKUP(C21,Telemetria!C$1:E$99,2,0) -> Instalacion Lista | F21: Si | G21: =VLOOKUP(C21,'Hoja 27'!C$1:E$63,3,0) -> Si cuenta con RS | H21: =VLOOKUP(C21,'Hoja 33'!B$2:E$67,1,0) -> #REF! | I21: ✅ | J21: ✅ | K21: ✅ | M21: ❌
A22: 121 (Punta Arenas) | B22: HDVSVDZC94 | C22: =RIGHT(B22,6) -> VDZC94 | D22: Activa | E22: =VLOOKUP(C22,Telemetria!C$1:E$99,2,0) -> Instalacion Lista | F22: Si | G22: =VLOOKUP(C22,'Hoja 27'!C$1:E$63,3,0) -> Si cuenta con RS | H22: =VLOOKUP(C22,'Hoja 33'!B$2:E$67,1,0) -> #REF! | I22: ✅ | J22: ✅ | K22: ✅ | M22: ❌
A23: 121 (Punta Arenas) | B23: HDVSVLHB59 | C23: =RIGHT(B23,6) -> VLHB59 | D23: Activa | E23: =VLOOKUP(C23,Telemetria!C$1:E$99,2,0) -> Instalacion Lista | F23: Si | G23: =VLOOKUP(C23,'Hoja 27'!C$1:E$63,3,0) -> Si cuenta con RS | H23: =VLOOKUP(C23,'Hoja 33'!B$2:E$67,1,0) -> #REF! | I23: ✅ | J23: ✅ | K23: ❌ | M23: ❌ | N23: Cambiar separador
A24: 121 (Punta Arenas) | B24: HDVSVSGW69 | C24: =RIGHT(B24,6) -> VSGW69 | D24: Activa | E24: =VLOOKUP(C24,Telemetria!C$1:E$99,2,0) -> Instalacion Lista | F24: No | G24: =VLOOKUP(C24,'Hoja 27'!C$1:E$63,3,0) -> Si cuenta con RS | H24: =VLOOKUP(C24,'Hoja 33'!B$2:E$67,1,0) -> #REF! | I24: ❌ | J24: ✅ | K24: ✅ | M24: ❌ | N24: Coordinar instalacion
A25: 58 (Viña del mar) | B25: HDVSDLCB16 | C25: =RIGHT(B25,6) -> DLCB16 | D25: Panne | E25: =VLOOKUP(C25,Telemetria!C$1:E$99,2,0) -> Instalacion Lista | F25: Si | G25: =VLOOKUP(C25,'Hoja 27'!C$1:E$63,3,0) -> Si cuenta con RS | H25: =VLOOKUP(C25,'Hoja 33'!B$2:E$67,1,0) -> #REF! | I25: ✅ | J25: ✅ | K25: ✅ | M25: ❌
A26: 58 (Viña del mar) | B26: HDVSPPWY63 | C26: =RIGHT(B26,6) -> PPWY63 | D26: Activa | E26: =VLOOKUP(C26,Telemetria!C$1:E$99,2,0) -> Instalacion Lista | F26: Si | G26: =VLOOKUP(C26,'Hoja 27'!C$1:E$63,3,0) -> Si cuenta con RS | H26: =VLOOKUP(C26,'Hoja 33'!B$2:E$67,1,0) -> #REF! | I26: ✅ | J26: ✅ | K26: ✅ | M26: ❌
A27: 58 (Viña del mar) | B27: HDVSSRYH57 | C27: =RIGHT(B27,6) -> SRYH57 | D27: Activa | E27: =VLOOKUP(C27,Telemetria!C$1:E$99,2,0) -> Instalacion Lista | F27: Si | G27: =VLOOKUP(C27,'Hoja 27'!C$1:E$63,3,0) -> Si cuenta con RS | H27: =VLOOKUP(C27,'Hoja 33'!B$2:E$67,1,0) -> #REF! | I27: ✅ | J27: ✅ | K27: ✅ | M27: ❌
A28: 58 (Viña del mar) | B28: HDVSSTWR86 | C28: =RIGHT(B28,6) -> STWR86 | D28: Activa | E28: =VLOOKUP(C28,Telemetria!C$1:E$99,2,0) -> Pendiente Instalacion | F28: Si | G28: =VLOOKUP(C28,'Hoja 27'!C$1:E$63,3,0) -> Si cuenta con RS | H28: =VLOOKUP(C28,'Hoja 33'!B$2:E$67,1,0) -> #REF! | I28: ✅ | J28: ✅ | K28: ✅ | M28: ❌
A29: 58 (Viña del mar) | B29: HDVSSVLY73 | C29: =RIGHT(B29,6) -> SVLY73 | D29: Activa | E29: =VLOOKUP(C29,Telemetria!C$1:E$99,2,0) -> Instalacion Lista | F29: Si | G29: =VLOOKUP(C29,'Hoja 27'!C$1:E$63,3,0) -> No se encuentra documentación | H29: =VLOOKUP(C29,'Hoja 33'!B$2:E$67,1,0) -> #REF! | I29: ❌ | J29: ✅ | K29: ✅ | M29: ❌
A30: 58 (Viña del mar) | B30: HDVSSYSS70 | C30: =RIGHT(B30,6) -> SYSS70 | D30: Activa | E30: =VLOOKUP(C30,Telemetria!C$1:E$99,2,0) -> Instalacion Lista | F30: Si | G30: =VLOOKUP(C30,'Hoja 27'!C$1:E$63,3,0) -> Si cuenta con RS | H30: =VLOOKUP(C30,'Hoja 33'!B$2:E$67,1,0) -> #REF! | I30: ✅ | J30: ✅ | K30: ✅ | M30: ❌ | N30: Branding comppleto
A31: 58 (Viña del mar) | B31: HDVSTPXY11 | C31: =RIGHT(B31,6) -> TPXY11 | D31: Activa | E31: =VLOOKUP(C31,Telemetria!C$1:E$99,2,0) -> Pendiente Instalacion | F31: Si | G31: =VLOOKUP(C31,'Hoja 27'!C$1:E$63,3,0) -> Si cuenta con RS | H31: =VLOOKUP(C31,'Hoja 33'!B$2:E$67,1,0) -> #REF! | I31: ❌ | J31: ✅ | K31: ✅ | M31: ❌ | N31: No tiene branding
A32: 58 (Viña del mar) | B32: HDVSTVZC13 | C32: =RIGHT(B32,6) -> TVZC13 | D32: Panne | E32: =VLOOKUP(C32,Telemetria!C$1:E$99,2,0) -> Instalacion Lista | F32: Si | G32: =VLOOKUP(C32,'Hoja 27'!C$1:E$63,3,0) -> No se encuentra resolución sanitaria | H32: =VLOOKUP(C32,'Hoja 33'!B$2:E$67,1,0) -> #REF! | I32: ✅ | J32: ✅ | K32: ✅ | M32: ❌
A33: 58 (Viña del mar) | B33: HDVSVHSW61 | C33: =RIGHT(B33,6) -> VHSW61 | D33: Activa | E33: =VLOOKUP(C33,Telemetria!C$1:E$99,2,0) -> Instalacion Lista | F33: Si | G33: =VLOOKUP(C33,'Hoja 27'!C$1:E$63,3,0) -> Si cuenta con RS | H33: =VLOOKUP(C33,'Hoja 33'!B$2:E$67,1,0) -> #REF! | I33: ✅ | J33: ✅ | K33: ✅ | M33: ❌
A34: 58 (Viña del mar) | B34: HDVSTSTP28 | C34: =RIGHT(B34,6) -> TSTP28 | D34: Activa | E34: =VLOOKUP(C34,Telemetria!C$1:E$99,2,0) -> Instalacion Lista | F34: No | G34: =VLOOKUP(C34,'Hoja 27'!C$1:E$63,3,0) -> Si cuenta con RS | H34: =VLOOKUP(C34,'Hoja 33'!B$2:E$67,1,0) -> #REF! | I34: ❌ | J34: ❌ | K34: ✅ | M34: ❌ | N34: Branding incompleto/Lamas feas
A35: 608 (Chillan) | B35: HDVSHZPB58 | C35: =RIGHT(B35,6) -> HZPB58 | D35: Activa | E35: =VLOOKUP(C35,Telemetria!C$1:E$99,2,0) -> Instalacion Lista | F35: Si | G35: =VLOOKUP(C35,'Hoja 27'!C$1:E$63,3,0) -> Si cuenta con RS | H35: =VLOOKUP(C35,'Hoja 33'!B$2:E$67,1,0) -> #REF! | I35: ❌ | J35: ❌ | K35: ❌ | M35: ❌
A36: 608 (Chillan) | B36: HDVSVKDZ87 | C36: =RIGHT(B36,6) -> VKDZ87 | D36: Activa | E36: =VLOOKUP(C36,Telemetria!C$1:E$99,2,0) -> Instalacion Lista | G36: =VLOOKUP(C36,'Hoja 27'!C$1:E$63,3,0) -> #N/A | H36: =VLOOKUP(C36,'Hoja 33'!B$2:E$67,1,0) -> #REF! | I36: Pendiente | J36: Pendiente | K36: Pendiente
A37: 608 (Chillan) | B37: HDVSTWRJ22 | C37: =RIGHT(B37,6) -> TWRJ22 | D37: Activa | E37: =VLOOKUP(C37,Telemetria!C$1:E$99,2,0) -> Instalacion Lista | G37: =VLOOKUP(C37,'Hoja 27'!C$1:E$63,3,0) -> No se encuentra documentación | H37: =VLOOKUP(C37,'Hoja 33'!B$2:E$67,1,0) -> #REF! | I37: Pendiente | J37: Pendiente | K37: Pendiente
A38: 608 (Chillan) | B38: HDVSTFBY52 | C38: =RIGHT(B38,6) -> TFBY52 | D38: Activa | E38: =VLOOKUP(C38,Telemetria!C$1:E$99,2,0) -> Pendiente Instalacion | F38: No | G38: =VLOOKUP(C38,'Hoja 27'!C$1:E$63,3,0) -> Si cuenta con RS | H38: =VLOOKUP(C38,'Hoja 33'!B$2:E$67,1,0) -> #REF! | I38: Pendiente | J38: Pendiente | K38: Pendiente | M38: ❌ | N38: coordinar instalacion
A39: 618 (Osorno) | B39: HDVSFZKB60 | C39: =RIGHT(B39,6) -> FZKB60 | D39: Activa | E39: =VLOOKUP(C39,Telemetria!C$1:E$99,2,0) -> Instalacion Lista | F39: Pendiente | G39: =VLOOKUP(C39,'Hoja 27'!C$1:E$63,3,0) -> Si cuenta con RS | H39: =VLOOKUP(C39,'Hoja 33'!B$2:E$67,1,0) -> #REF! | I39: ✅ | J39: ✅ | K39: ✅ | M39: ❌
A40: 618 (Osorno) | B40: HDVSJSTD66 | C40: =RIGHT(B40,6) -> JSTD66 | D40: Activa | E40: =VLOOKUP(C40,Telemetria!C$1:E$99,2,0) -> Pendiente Instalacion | F40: Pendiente | G40: =VLOOKUP(C40,'Hoja 27'!C$1:E$63,3,0) -> Si cuenta con RS | H40: =VLOOKUP(C40,'Hoja 33'!B$2:E$67,1,0) -> #REF! | I40: ✅ | J40: ✅ | K40: ✅ | M40: ❌ | N40: coordinar instalacion
...

Sheet Flota actual VS
B1: Flota Cyber 2026
A2: TIpo | B2: Local | C2: Patente | D2: Status | E2: Observacion
A3: FH | B3: L58 | C3: SYSS70 | D3: Activo
A4: FH | B4: L58 | C4: PPWY63 | D4: Activo
A5: FH | B5: L58 | C5: SRYH57 | D5: Activo
A6: FH | B6: L58 | C6: STWR86 | D6: Activo
A7: FH | B7: L58 | C7: TPXY11 | D7: No operativo | E7: Panne
A8: FH | B8: L58 | C8: VHSW61 | D8: Activo
A9: FH | B9: L58 | C9: TVZC13 | D9: Activo
A10: FH | B10: L58 | C10: DLCB16 | D10: No operativo | E10: Panne
A11: FH | B11: L58 | C11: SVLY73 | D11: Activo | E11: 983
A12: FH | B12: L58 | C12: TSTP28 | D12: No operativo | E12: 983
A13: FH | B13: L94 | C13: TRYL78 | D13: Activo
A14: FH | B14: L94 | C14: VJPH80 | D14: Activo
A15: FH | B15: L94 | C15: VJWK44 | D15: Activo
A16: FH | B16: L94 | C16: VGWW22 | D16: Activo
A17: FH | B17: L94 | C17: LRXY26 | D17: Activo
A18: FH | B18: L94 | C18: PGHD38 | D18: No operativo | E18: Panne
A19: FH | B19: L94 | C19: VJRT63 | D19: Activo
A20: FH | B20: L98 | C20: KSXP45 | D20: Activo
A21: FH | B21: L98 | C21: RTTR83 | D21: Activo
A22: FH | B22: L98 | C22: SDYY74 | D22: Activo
A23: FH | B23: L98 | C23: TRPP43 | D23: Activo
A24: FH | B24: L98 | C24: VKJF15 | D24: Activo
A25: FH | B25: L98 | C25: RDLW17 | D25: No operativo | E25: Falta piso(Revisar)
A26: FH | B26: L98 | C26: PCFZ21 | D26: Activo
A27: FH | B27: L98 | C27: VDSH17 | D27: Activo
A28: FH | B28: L98 | C28: PRFC70 | D28: Activo
A29: FH | B29: L98 | C29: RBYF40 | D29: Activo
A30: FH | B30: L98 | C30: RPWK21 | D30: Activo
A31: FH | B31: L98 | C31: SKXW43 | D31: Activo
A32: FH | B32: L98 | C32: TJDR58 | D32: Activo
A33: FH | B33: L98 | C33: LSVH23 | D33: Activo
A34: FH | B34: L98 | C34: PCJZ43 | D34: Activo
A35: FH | B35: L99 | C35: LHZW29 | D35: Activo
A36: FH | B36: L99 | C36: VJWK40 | D36: Activo
A37: FH | B37: L99 | C37: VJWK39 | D37: Activo
... A39: FH | B39: L99 | C39: LLXD43 | D39: Activo
A40: FH | B40: L99 | C40: VJPH72 | D40: No operativo | E40: Parte 29/05
A41: FH | B41: L99 | C41: VJPH79 | D41: No operativo | E41: Parte 29/05
...

Sheet Check FLE
A1: REPARACIÓN CAMIONETAS ELÉCTRICAS
A2: TTHR12 | C2: TTHR19 | E2: TTHP82 | G2: TTHP92 | I2: TTHP93 | K2: TTHP95
A3: Pendiente / detalle | B3: Listo | C3: Pendiente / detalle | D3: Listo | E3: Pendiente / detalle | F3: Listo | G3: Pendiente / detalle | H3: Listo | I3: Pendiente / detalle | J3: Listo | K3: Pendiente / detalle | L3: Listo
A4: TMK no funciona | B4: FALSE | C4: Buen estado general | D4: TRUE | E4: TMK no funciona | F4: FALSE | G4: TMK no funciona | H4: FALSE | I4: TMK no funciona | J4: FALSE | K4: Cámara mala | L4: FALSE
A5: Parabrisa quebrado / cambio urgente | B5: TRUE | E5: Focos delanteros malos | F5: FALSE | G5: Focos delanteros malos | H5: FALSE | I5: Focos delanteros malos | J5: TRUE
E6: Sin grabado de patente | F6: FALSE | I6: Cámara mala | J6: FALSE
E7: Sin branding | F7: FALSE
A9: % Cumplimiento | B9: =COUNTIF(B4:B5,TRUE)/2 -> 0.5 | C9: % Cumplimiento | D9: =COUNTIF(D4,TRUE)/1 -> 1 | E9: % Cumplimiento | F9: =COUNTIF(F4:F7,TRUE)/4 -> 0 | G9: % Cumplimiento | H9: =COUNTIF(H4:H5,TRUE)/2 -> 0 | I9: % Cumplimiento | J9: =COUNTIF(J4:J6,TRUE)/3 -> 0.33333333 | K9: % Cumplimiento | L9: =COUNTIF(L4,TRUE)/1 -> 0
A10: % Pendiente | B10: =1-B9 -> 0.5 | C10: % Pendiente | D10: =1-D9 -> 0 | E10: % Pendiente | F10: =1-F9 -> 1 | G10: % Pendiente | H10: =1-H9 -> 1 | I10: % Pendiente | J10: =1-J9 -> 0.66666667 | K10: % Pendiente | L10: =1-L9 -> 1
A11: Estado | B11: =IF(B9=1,"LISTO","PENDIENTE") -> PENDIENTE | C11: Estado | D11: =IF(D9=1,"LISTO","PENDIENTE") -> LISTO | E11: Estado | F11: =IF(F9=1,"LISTO","PENDIENTE") -> PENDIENTE | G11: Estado | H11: =IF(H9=1,"LISTO","PENDIENTE") -> PENDIENTE | I11: Estado | J11: =IF(J9=1,"LISTO","PENDIENTE") -> PENDIENTE | K11: Estado | L11: =IF(L9=1,"LISTO","PENDIENTE") -> PENDIENTE

Sheet Revision RS
A1: CONTROL RESOLUCIÓN SANITARIA- FALTANTES FLOTA FH
A2: Local | B2: Patente | C2: Estatus | D2: Observación | E2: % Avance
A3: L120 (Temuco) | B3: TKWX57 | C3: Pendiente | D3: No responde | E3: =IF(C3="Listo",1,0) -> 0
A4: L120 (Temuco) | B4: TRYL82 | C4: Pendiente | D4: VS | E4: =IF(C4="Listo",1,0) -> 0
A5: L120 (Temuco) | B5: TSCT51 | C5: Pendiente | D5: VS | E5: =IF(C5="Listo",1,0) -> 0
A6: 121 (Punta Arenas) | B6: PSLP82 | C6: Pendiente | D6: Proceso | E6: =IF(C6="Listo",1,0) -> 0
A7: 58 (Viña del Mar) | B7: SVLY73 | C7: Pendiente | D7: Proceso | E7: =IF(C7="Listo",1,0) -> 0
A8: 618 (Osorno) | B8: VKFD45 | C8: Listo | D8: listo | E8: =IF(C8="Listo",1,0) -> 1
A9: 94 (Valdivia) | B9: TRYL78 | C9: Pendiente | D9: VS | E9: =IF(C9="Listo",1,0) -> 0
A10: 94 (Valdivia) | B10: VGWW22 | C10: Pendiente | D10: Proceso | E10: =IF(C10="Listo",1,0) -> 0
A11: 99 (Puerto Montt) | B11: JTYF43 | C11: Pendiente | D11: Proceso | E11: =IF(C11="Listo",1,0) -> 0
A12: 99 (Puerto Montt) | B12: LLXD43 | C12: Pendiente | D12: Proceso | E12: =IF(C12="Listo",1,0) -> 0

Sheet Horarios IH
C1: 46143 | D1: 46144 | E1: 46145 | G1: 46146 | H1: 46147 | I1: 46148 | J1: 46149 | K1: 46150 | L1: 46151 | M1: 46152 | O1: 46153 | P1: 46154 | Q1: 46155 | R1: 46156 | S1: 46157 | T1: 46158 | U1: 46159 | W1: 46160 | X1: 46161 | Y1: 46162 | Z1: 46163 | AA1: 46164 | AB1: 46165 | AC1: 46166 | AE1: 46167 | AF1: 46168 | AG1: 46169 | AH1: 46170 | AI1: 46171 | AJ1: 46172 | AK1: 46173 | AM1: 46174 | AN1: 46175 | AO1: 46176 | AP1: 46177 | AQ1: 46178 | AR1: 46179 | AS1: 46180 | AU1: 46181 | AV1: 46182 | AW1: 46183 | AX1: 46184 | AY1: 46185 | AZ1: 46186 | BA1: 46187 | BC1: 46188 | BD1: 46189 | BE1: 46190 | BF1: 46191 | BG1: 46192 | BH1: 46193 | BI1: 46194 | BK1: 46195 | BL1: 46196 | BM1: 46197 | BN1: 46198 | BO1: 46199 | BP1: 46200 | BQ1: 46201 | BS1: 46202 | BT1: 46203
C2: viernes | D2: sabado | E2: domingo | G2: lunes | H2: martes | I2: miércoles | J2: jueves | K2: viernes | L2: sábado | M2: domingo | O2: lunes | P2: martes | Q2: miércoles | R2: jueves | S2: viernes | T2: sábado | U2: domingo | W2: lunes | X2: martes | Y2: miércoles | Z2: jueves | AA2: viernes | AB2: sábado | AC2: domingo | AE2: lunes | AF2: martes | AG2: miércoles | AH2: jueves | AI2: viernes | AJ2: sábado | AK2: domingo | AL2: horas extras | AM2: lunes | AN2: martes | AO2: miércoles | AP2: jueves | AQ2: viernes | AR2: sábado | AS2: domingo | AU2: lunes | AV2: martes | AW2: miércoles | AX2: jueves | AY2: viernes | AZ2: sábado | BA2: domingo | BC2: lunes | BD2: martes | BE2: miércoles | BF2: jueves | BG2: viernes | BH2: sábado | BI2: domingo | BK2: lunes | BL2: martes | BM2: miércoles | BN2: jueves | BO2: viernes | BP2: sábado | BQ2: domingo | BS2: lunes | BT2: martes
A3: Local 58 | B3: Macarena Andrea Ibaceta Cabrera | C3: Libre | D3: FULL | E3: Libre | G3: Libre | H3: FULL | I3: Libre | J3: Libre | K3: comp | L3: FULL | M3: FULL | O3: FULL | P3: Libre | Q3: FULL | R3: FULL | S3: FULL | T3: Libre | U3: Libre | W3: FULL | X3: FULL | Y3: Libre | Z3: Libre | AA3: Libre | AB3: FULL | AC3: FULL | AE3: FULL | AF3: Libre | AG3: FULL | AH3: FULL | AI3: FULL | AJ3: Libre | AK3: Libre | AM3: =IF(LOWER(TRIM($AL$2))="compensado",Compensado!B3,'Horas extras'!B3) -> #REF! | AN3: =IF(LOWER(TRIM($AL$2))="compensado",Compensado!C3,'Horas extras'!C3) -> #REF! | AO3: Libre | AP3: =IF(LOWER(TRIM($AL$2))="compensado",Compensado!E3,'Horas extras'!E3) -> #REF! | AQ3: =IF(LOWER(TRIM($AL$2))="compensado",Compensado!F3,'Horas extras'!F3) -> #REF! | AR3: =IF(LOWER(TRIM($AL$2))="compensado",Compensado!G3,'Horas extras'!G3) -> #REF! | AS3: =IF(LOWER(TRIM($AL$2))="compensado",Compensado!H3,'Horas extras'!H3) -> #REF! | AT3: =IF(LOWER(TRIM($AL$2))="compensado",Compensado!I3,'Horas extras'!I3) -> #REF! | AU3: =IF(LOWER(TRIM($AL$2))="compensado",Compensado!J3,'Horas extras'!J3) -> #REF! | AV3: =IF(LOWER(TRIM($AL$2))="compensado",Compensado!K3,'Horas extras'!K3) -> #REF! | AW3: =IF(LOWER(TRIM($AL$2))="compensado",Compensado!L3,'Horas extras'!L3) -> #REF! | ... BT3: =IF(LOWER(TRIM($AL$2))="compensado",Compensado!AI3,'Horas extras'!AI3) -> #REF!
A4: Local 58 | B4: Rodrigo Orlando Mora Vera | C4: Libre | D4: Libre | E4: Libre | G4: FULL | H4: FULL | I4: Libre | J4: Libre | K4: Libre | L4: FULL | M4: FULL | O4: FULL | P4: Libre | Q4: FULL | R4: FULL | S4: FULL | T4: Libre | U4: Libre | W4: Libre | X4: FULL | Y4: Libre | Z4: Libre | AA4: FULL | AB4: FULL | AC4: FULL | AE4: FULL | AF4: Libre | AG4: FULL | AH4: FULL | AI4: FULL | AJ4: Libre | AK4: Libre | AM4: Libre | AN4: =IF(LOWER(TRIM($AL$2))="compensado",Compensado!C4,'Horas extras'!C4) -> #REF! | AO4: Libre | AP4: =IF(LOWER(TRIM($AL$2))="compensado",Compensado!E4,'Horas extras'!E4) -> #REF! | AQ4: =IF(LOWER(TRIM($AL$2))="compensado",Compensado!F4,'Horas extras'!F4) -> #REF! | AR4: =IF(LOWER(TRIM($AL$2))="compensado",Compensado!G4,'Horas extras'!G4) -> #REF! | AS4: =IF(LOWER(TRIM($AL$2))="compensado",Compensado!H4,'Horas extras'!H4) -> #REF! | AT4: =IF(LOWER(TRIM($AL$2))="compensado",Compensado!I4,'Horas extras'!I4) -> #REF! | AU4: =IF(LOWER(TRIM($AL$2))="compensado",Compensado!J4,'Horas extras'!J4) -> #REF! | AV4: =IF(LOWER(TRIM($AL$2))="compensado",Compensado!K4,'Horas extras'!K4) -> #REF! | AW4: =IF(LOWER(TRIM($AL$2))="compensado",Compensado!L4,'Horas extras'!L4) -> #REF! | ... BT4: =IF(LOWER(TRIM($AL$2))="compensado",Compensado!AI4,'Horas extras'!AI4) -> #REF!
A5: Local 58 | B5: Felipe Carvallo | C5: Libre | D5: FULL | E5: FULL | G5: FULL | H5: Libre | I5: FULL | J5: FULL | K5: FULL | L5: Libre | M5: Libre | O5: FULL | P5: FULL | Q5: Libre | R5: Libre | S5: Libre | T5: FULL | U5: FULL | W5: FULL | X5: Libre | Y5: FULL | Z5: FULL | AA5: FULL | AB5: Libre | AC5: Libre | AE5: FULL | AF5: FULL | AG5: Libre | AH5: Libre | AI5: Libre | AJ5: FULL | AK5: FULL | AM5: =IF(LOWER(TRIM($AL$2))="compensado",Compensado!B5,'Horas extras'!B5) -> #REF! | AN5: Libre | AO5: =IF(LOWER(TRIM($AL$2))="compensado",Compensado!D5,'Horas extras'!D5) -> #REF! | AP5: =IF(LOWER(TRIM($AL$2))="compensado",Compensado!E5,'Horas extras'!E5) -> #REF! | AQ5: =IF(LOWER(TRIM($AL$2))="compensado",Compensado!F5,'Horas extras'!F5) -> #REF! | AR5: =IF(LOWER(TRIM($AL$2))="compensado",Compensado!G5,'Horas extras'!G5) -> #REF! | AS5: =IF(LOWER(TRIM($AL$2))="compensado",Compensado!H5,'Horas extras'!H5) -> #REF! | AT5: =IF(LOWER(TRIM($AL$2))="compensado",Compensado!I5,'Horas extras'!I5) -> #REF! | AU5: =IF(LOWER(TRIM($AL$2))="compensado",Compensado!J5,'Horas extras'!J5) -> #REF! | AV5: =IF(LOWER(TRIM($AL$2))="compensado",Compensado!K5,'Horas extras'!K5) -> #REF! | ... BT5: =IF(LOWER(TRIM($AL$2))="compensado",Compensado!AI5,'Horas extras'!AI5) -> #REF!
A6: Local 58 | B6: Fabian Soto | C6: Libre | D6: FULL | E6: FULL | G6: FULL | H6: Libre | I6: FULL | J6: FULL | K6: FULL | L6: Libre | M6: Libre | O6: Libre | P6: FULL | Q6: Libre | R6: Libre | S6: comp | T6: FULL | U6: FULL | W6: FULL | X6: Libre | Y6: FULL | Z6: FULL | AA6: FULL | AB6: Libre | AC6: Libre | AE6: Libre | AF6: FULL | AG6: Libre | AH6: Libre | AI6: FULL | AJ6: FULL | AK6: FULL | AM6: =IF(LOWER(TRIM($AL$2))="compensado",Compensado!B6,'Horas extras'!B6) -> #REF! | AN6: Libre | AO6: =IF(LOWER(TRIM($AL$2))="compensado",Compensado!D6,'Horas extras'!D6) -> #REF! | AP6: =IF(LOWER(TRIM($AL$2))="compensado",Compensado!E6,'Horas extras'!E6) -> #REF! | AQ6: =IF(LOWER(TRIM($AL$2))="compensado",Compensado!F6,'Horas extras'!F6) -> #REF! | AR6: =IF(LOWER(TRIM($AL$2))="compensado",Compensado!G6,'Horas extras'!G6) -> #REF! | AS6: =IF(LOWER(TRIM($AL$2))="compensado",Compensado!H6,'Horas extras'!H6) -> #REF! | AT6: =IF(LOWER(TRIM($AL$2))="compensado",Compensado!I6,'Horas extras'!I6) -> #REF! | AU6: =IF(LOWER(TRIM($AL$2))="compensado",Compensado!J6,'Horas extras'!J6) -> #REF! | AV6: =IF(LOWER(TRIM($AL$2))="compensado",Compensado!K6,'Horas extras'!K6) -> #REF! | ... BT6: =IF(LOWER(TRIM($AL$2))="compensado",Compensado!AI6,'Horas extras'!AI6) -> #REF!
C7: =COUNTIFS(C3:C6, "full") -> 0 | D7: =COUNTIFS(D3:D6, "full") -> 3 | E7: =COUNTIFS(E3:E6, "full") -> 2 | G7: =COUNTIFS(G3:G6, "full") -> 3 | H7: =COUNTIFS(H3:H6, "full") -> 2 | I7: =COUNTIFS(I3:I6, "full") -> 2 | J7: =COUNTIFS(J3:J6, "full") -> 2 | K7: =COUNTIFS(K3:K6, "full") -> 2 | L7: =COUNTIFS(L3:L6, "full") -> 2 | M7: =COUNTIFS(M3:M6, "full") -> 2 | O7: =COUNTIFS(O3:O6, "full") -> 3 | P7: =COUNTIFS(P3:P6, "full") -> 2 | Q7: =COUNTIFS(Q3:Q6, "full") -> 2 | R7: =COUNTIFS(R3:R6, "full") -> 2 | S7: =COUNTIFS(S3:S6, "full") -> 2 | T7: =COUNTIFS(T3:T6, "full") -> 2 | U7: =COUNTIFS(U3:U6, "full") -> 2 | W7: =COUNTIFS(W3:W6, "full") -> 3 | X7: =COUNTIFS(X3:X6, "full") -> 2 | Y7: =COUNTIFS(Y3:Y6, "full") -> 2 | Z7: =COUNTIFS(Z3:Z6, "full") -> 2 | AA7: =COUNTIFS(AA3:AA6, "full") -> 3 | AB7: =COUNTIFS(AB3:AB6, "full") -> 2 | AC7: =COUNTIFS(AC3:AC6, "full") -> 2 | AE7: =COUNTIFS(AE3:AE6, "full") -> 3 | AF7: =COUNTIFS(AF3:AF6, "full") -> 2 | AG7: =COUNTIFS(AG3:AG6, "full") -> 2 | AH7: =COUNTIFS(AH3:AH6, "full") -> 2 | AI7: =COUNTIFS(AI3:AI6, "full") -> 3 | AJ7: =COUNTIFS(AJ3:AJ6, "full") -> 2 | AK7: =COUNTIFS(AK3:AK6, "full") -> 2 | AM7: =COUNTIFS(AM3:AM6, "full") -> 0 | AN7: =COUNTIFS(AN3:AN6, "full") -> 0 | AO7: =COUNTIFS(AO3:AO6, "full") -> 0 | AP7: =COUNTIFS(AP3:AP6, "full") -> 0 | AQ7: =COUNTIFS(AQ3:AQ6, "full") -> 0 | AR7: =COUNTIFS(AR3:AR6, "full") -> 0 | AS7: =COUNTIFS(AS3:AS6, "full") -> 0 | AU7: =COUNTIFS(AU3:AU6, "full") -> 0 | AV7: =COUNTIFS(AV3:AV6, "full") -> 0 | AW7: =COUNTIFS(AW3:AW6, "full") -> 0 | AX7: =COUNTIFS(AX3:AX6, "full") -> 0 | AY7: =COUNTIFS(AY3:AY6, "full") -> 0 | AZ7: =COUNTIFS(AZ3:AZ6, "full") -> 0 | BA7: =COUNTIFS(BA3:BA6, "full") -> 0 | BC7: =COUNTIFS(BC3:BC6, "full") -> 0 | BD7: =COUNTIFS(BD3:BD6, "full") -> 0 | BE7: =COUNTIFS(BE3:BE6, "full") -> 0 | BF7: =COUNTIFS(BF3:BF6, "full") -> 0 | BG7: =COUNTIFS(BG3:BG6, "full") -> 0 | BH7: =COUNTIFS(BH3:BH6, "full") -> 0 | BI7: =COUNTIFS(BI3:BI6, "full") -> 0 | BK7: =COUNTIFS(BK3:BK6, "full") -> 0 | BL7: =COUNTIFS(BL3:BL6, "full") -> 0 | BM7: =COUNTIFS(BM3:BM6, "full") -> 0 | BN7: =COUNTIFS(BN3:BN6, "full") -> 0 | BO7: =COUNTIFS(BO3:BO6, "full") -> 0 | BP7: =COUNTIFS(BP3:BP6, "full") -> 0 | BQ7: =COUNTIFS(BQ3:BQ6, "full") -> 0 | BS7: =COUNTIFS(BS3:BS6, "full") -> 0 | BT7: =COUNTIFS(BT3:BT6, "full") -> 0
A9: Local 45 | B9: claudia | C9: Libre | D9: FULL | E9: Libre | G9: FULL | H9: FULL | I9: Libre | J9: Libre | K9: Libre | L9: FULL | M9: FULL | O9: FULL | P9: Libre | Q9: FULL | R9: FULL | S9: FULL | T9: Libre | U9: Libre | W9: FULL | X9: FULL | Y9: Libre | Z9: Libre | AA9: Libre | AB9: FULL | AC9: FULL | AE9: FULL | AF9: Libre | AG9: FULL | AH9: FULL | AI9: FULL | AJ9: Libre | AK9: Libre | AL9: horas extras | AM9: =IF(LOWER(TRIM($AL$9))="compensado",Compensado!B3,'Horas extras'!B3) -> #REF! | AN9: =IF(LOWER(TRIM($AL$9))="compensado",Compensado!C3,'Horas extras'!C3) -> #REF! | AO9: Libre | AP9: Libre | AQ9: =IF(LOWER(TRIM($AL$9))="compensado",Compensado!F3,'Horas extras'!F3) -> #REF! | AR9: =IF(LOWER(TRIM($AL$9))="compensado",Compensado!G3,'Horas extras'!G3) -> #REF! | AS9: =IF(LOWER(TRIM($AL$9))="compensado",Compensado!H3,'Horas extras'!H3) -> #REF! | AT9: =IF(LOWER(TRIM($AL$9))="compensado",Compensado!I3,'Horas extras'!I3) -> #REF! | AU9: =IF(LOWER(TRIM($AL$9))="compensado",Compensado!J3,'Horas extras'!J3) -> #REF! | AV9: =IF(LOWER(TRIM($AL$9))="compensado",Compensado!K3,'Horas extras'!K3) -> #REF! | AW9: =IF(LOWER(TRIM($AL$9))="compensado",Compensado!L3,'Horas extras'!L3) -> #REF! | AX9: =IF(LOWER(TRIM($AL$9))="compensado",Compensado!M3,'Horas extras'!M3) -> #REF! | ... BT9: =IF(LOWER(TRIM($AL$9))="compensado",Compensado!AI3,'Horas extras'!AI3) -> #REF!
A10: Local 45 | B10: Victor Daniel Valero Gomez | C10: Libre | D10: Libre | E10: FULL | G10: Libre | H10: FULL | I10: Libre | J10: Libre | K10: comp | L10: FULL | M10: FULL | O10: FULL | P10: Libre | Q10: FULL | R10: FULL | S10: FULL | T10: Libre | U10: Libre | W10: Libre | X10: FULL | Y10: Libre | Z10: Libre | AA10: FULL | AB10: FULL | AC10: FULL | AE10: FULL | AF10: Libre | AG10: FULL | AH10: FULL | AI10: FULL | AJ10: Libre | AK10: Libre | AM10: Libre | AN10: =IF(LOWER(TRIM($AL$9))="compensado",Compensado!C4,'Horas extras'!C4) -> #REF! | AO10: Extra | AP10: =IF(LOWER(TRIM($AL$9))="compensado",Compensado!E4,'Horas extras'!E4) -> #REF! | AQ10: =IF(LOWER(TRIM($AL$9))="compensado",Compensado!F4,'Horas extras'!F4) -> #REF! | AR10: =IF(LOWER(TRIM($AL$9))="compensado",Compensado!G4,'Horas extras'!G4) -> #REF! | AS10: =IF(LOWER(TRIM($AL$9))="compensado",Compensado!H4,'Horas extras'!H4) -> #REF! | AT10: =IF(LOWER(TRIM($AL$9))="compensado",Compensado!I4,'Horas extras'!I4) -> #REF! | AU10: =IF(LOWER(TRIM($AL$9))="compensado",Compensado!J4,'Horas extras'!J4) -> #REF! | AV10: =IF(LOWER(TRIM($AL$9))="compensado",Compensado!K4,'Horas extras'!K4) -> #REF! | AW10: =IF(LOWER(TRIM($AL$9))="compensado",Compensado!L4,'Horas extras'!L4) -> #REF! | ... BT10: =IF(LOWER(TRIM($AL$9))="compensado",Compensado!AI4,'Horas extras'!AI4) -> #REF!
A11: Local 45 | B11: Maximiliano Vicente Abrigo Vidal | C11: Libre | D11: FULL | E11: Libre | G11: FULL | H11: Libre | I11: FULL | J11: FULL | K11: FULL | L11: Libre | M11: Libre | O11: FULL | P11: FULL | Q11: Libre | R11: Libre | S11: Libre | T11: VAC | U11: VAC | W11: VAC | X11: Libre | Y11: VAC | Z11: VAC | AA11: VAC | AB11: Libre | AC11: Libre | AE11: VAC | AF11: FULL | AG11: Libre | AH11: Libre | AI11: Libre | AJ11: FULL | AK11: FULL | AM11: =IF(LOWER(TRIM($AL$9))="compensado",Compensado!B5,'Horas extras'!B5) -> #REF! | AN11: FULL | AO11: =IF(LOWER(TRIM($AL$9))="compensado",Compensado!D5,'Horas extras'!D5) -> #REF! | AP11: =IF(LOWER(TRIM($AL$9))="compensado",Compensado!E5,'Horas extras'!E5) -> #REF! | AQ11: Libre | AR11: =IF(LOWER(TRIM($AL$9))="compensado",Compensado!G5,'Horas extras'!G5) -> #REF! | AS11: =IF(LOWER(TRIM($AL$9))="compensado",Compensado!H5,'Horas extras'!H5) -> #REF! | AT11: =IF(LOWER(TRIM($AL$9))="compensado",Compensado!I5,'Horas extras'!I5) -> #REF! | AU11: =IF(LOWER(TRIM($AL$9))="compensado",Compensado!J5,'Horas extras'!J5) -> #REF! | AV11: =IF(LOWER(TRIM($AL$9))="compensado",Compensado!K5,'Horas extras'!K5) -> #REF! | AW11: =IF(LOWER(TRIM($AL$9))="compensado",Compensado!L5,'Horas extras'!L5) -> #REF! | AX11: =IF(LOWER(TRIM($AL$9))="compensado",Compensado!M5,'Horas extras'!M5) -> #REF! | AY11: =IF(LOWER(TRIM($AL$9))="compensado",Compensado!N5,'Horas extras'!N5) -> #REF! | ... BT11: =IF(LOWER(TRIM($AL$9))="compensado",Compensado!AI5,'Horas extras'!AI5) -> #REF!
A12: Local 45 | B12: Adriana Katherine Ruiz Sanabria | C12: Libre | D12: FULL | E12: FULL | G12: FULL | H12: Libre | I12: FULL | J12: FULL | K12: FULL | L12: Libre | M12: Libre | O12: Libre | P12: FULL | Q12: Libre | R12: Libre | S12: comp | T12: FULL | U12: FULL | W12: FULL | X12: Libre | Y12: FULL | Z12: FULL | AA12: FULL | AB12: Libre | AC12: Libre | AE12: Libre | AF12: FULL | AG12: Libre | AH12: Libre | AI12: FULL | AJ12: FULL | AK12: comp | AM12: =IF(LOWER(TRIM($AL$9))="compensado",Compensado!B6,'Horas extras'!B6) -> #REF! | AN12: Libre | AO12: =IF(LOWER(TRIM($AL$9))="compensado",Compensado!D6,'Horas extras'!D6) -> #REF! | AP12: =IF(LOWER(TRIM($AL$9))="compensado",Compensado!E6,'Horas extras'!E6) -> #REF! | AQ12: =IF(LOWER(TRIM($AL$9))="compensado",Compensado!F6,'Horas extras'!F6) -> #REF! | AR12: =IF(LOWER(TRIM($AL$9))="compensado",Compensado!G6,'Horas extras'!G6) -> #REF! | AS12: =IF(LOWER(TRIM($AL$9))="compensado",Compensado!H6,'Horas extras'!H6) -> #REF! | AT12: =IF(LOWER(TRIM($AL$9))="compensado",Compensado!I6,'Horas extras'!I6) -> #REF! | AU12: =IF(LOWER(TRIM($AL$9))="compensado",Compensado!J6,'Horas extras'!J6) -> #REF! | AV12: =IF(LOWER(TRIM($AL$9))="compensado",Compensado!K6,'Horas extras'!K6) -> #REF! | ... AX12: =IF(LOWER(TRIM($AL$9))="compensado",Compensado!M6,'Horas extras'!M6) -> #REF! | AY12: fuLL | AZ12: =IF(LOWER(TRIM($AL$9))="compensado",Compensado!O6,'Horas extras'!O6) -> #REF! | BA12: =IF(LOWER(TRIM($AL$9))="compensado",Compensado!P6,'Horas extras'!P6) -> #REF! | BB12: =IF(LOWER(TRIM($AL$9))="compensado",Compensado!Q6,'Horas extras'!Q6) -> #REF! | BC12: =IF(LOWER(TRIM($AL$9))="compensado",Compensado!R6,'Horas extras'!R6) -> #REF! | BD12: =IF(LOWER(TRIM($AL$9))="compensado",Compensado!S6,'Horas extras'!S6) -> #REF! | BE12: =IF(LOWER(TRIM($AL$9))="compensado",Compensado!T6,'Horas extras'!T6) -> #REF! | BF12: =IF(LOWER(TRIM($AL$9))="compensado",Compensado!U6,'Horas extras'!U6) -> #REF! | BG12: =IF(LOWER(TRIM($AL$9))="compensado",Compensado!V6,'Horas extras'!V6) -> #REF! | ... BT12: =IF(LOWER(TRIM($AL$9))="compensado",Compensado!AI6,'Horas extras'!AI6) -> #REF!
C13: =COUNTIFS(C9:C12, "full") -> 0 | D13: =COUNTIFS(D9:D12, "full") -> 3 | E13: 3 | G13: =COUNTIFS(G9:G12, "full") -> 3 | H13: =COUNTIFS(H9:H12, "full") -> 2 | I13: =COUNTIFS(I9:I12, "full") -> 2 | J13: =COUNTIFS(J9:J12, "full") -> 2 | K13: =COUNTIFS(K9:K12, "full") -> 2 | L13: =COUNTIFS(L9:L12, "full") -> 2 | M13: =COUNTIFS(M9:M12, "full") -> 2 | O13: =COUNTIFS(O9:O12, "full") -> 3 | P13: =COUNTIFS(P9:P12, "full") -> 2 | Q13: =COUNTIFS(Q9:Q12, "full") -> 2 | R13: =COUNTIFS(R9:R12, "full") -> 2 | S13: =COUNTIFS(S9:S12, "full") -> 2 | T13: =COUNTIFS(T9:T12, "full") -> 1 | U13: =COUNTIFS(U9:U12, "full") -> 1 | W13: =COUNTIFS(W9:W12, "full") -> 2 | X13: =COUNTIFS(X9:X12, "full") -> 2 | Y13: =COUNTIFS(Y9:Y12, "full") -> 1 | Z13: =COUNTIFS(Z9:Z12, "full") -> 1 | AA13: =COUNTIFS(AA9:AA12, "full") -> 2 | AB13: =COUNTIFS(AB9:AB12, "full") -> 2 | AC13: =COUNTIFS(AC9:AC12, "full") -> 2 | AE13: =COUNTIFS(AE9:AE12, "full") -> 2 | AF13: =COUNTIFS(AF9:AF12, "full") -> 2 | AG13: =COUNTIFS(AG9:AG12, "full") -> 2 | AH13: =COUNTIFS(AH9:AH12, "full") -> 2 | AI13: =COUNTIFS(AI9:AI12, "full") -> 3 | AJ13: =COUNTIFS(AJ9:AJ12, "full") -> 2 | AK13: =COUNTIFS(AK9:AK12, "full") -> 1 | AM13: =COUNTIFS(AM9:AM12, "full") -> 0 | AN13: =COUNTIFS(AN9:AN12, "full") -> 1 | AO13: =COUNTIFS(AO9:AO12, "full") -> 0 | AP13: =COUNTIFS(AP9:AP12, "full") -> 0 | AQ13: =COUNTIFS(AQ9:AQ12, "full") -> 0 | AR13: =COUNTIFS(AR9:AR12, "full") -> 0 | AS13: =COUNTIFS(AS9:AS12, "full") -> 0 | AU13: =COUNTIFS(AU9:AU12, "full") -> 0 | AV13: =COUNTIFS(AV9:AV12, "full") -> 0 | AW13: =COUNTIFS(AW9:AW12, "full") -> 0 | AX13: =COUNTIFS(AX9:AX12, "full") -> 0 | AY13: =COUNTIFS(AY9:AY12, "full") -> 1 | AZ13: =COUNTIFS(AZ9:AZ12, "full") -> 0 | BA13: =COUNTIFS(BA9:BA12, "full") -> 0 | BC13: =COUNTIFS(BC9:BC12, "full") -> 0 | BD13: =COUNTIFS(BD9:BD12, "full") -> 0 | BE13: =COUNTIFS(BE9:BE12, "full") -> 0 | BF13: =COUNTIFS(BF9:BF12, "full") -> 0 | BG13: =COUNTIFS(BG9:BG12, "full") -> 0 | BH13: =COUNTIFS(BH9:BH12, "full") -> 0 | BI13: =COUNTIFS(BI9:BI12, "full") -> 0 | BK13: =COUNTIFS(BK9:BK12, "full") -> 0 | BL13: =COUNTIFS(BL9:BL12, "full") -> 0 | BM13: =COUNTIFS(BM9:BM12, "full") -> 0 | BN13: =COUNTIFS(BN9:BN12, "full") -> 0 | BO13: =COUNTIFS(BO9:BO12, "full") -> 0 | BP13: =COUNTIFS(BP9:BP12, "full") -> 0 | BQ13: =COUNTIFS(BQ9:BQ12, "full") -> 0 | BS13: =COUNTIFS(BS9:BS12, "full") -> 0 | BT13: =COUNTIFS(BT9:BT12, "full") -> 0
B14: La Reina
A15: Local 95 | B15: Vanessa | C15: LIBRE | D15: LIBRE | E15: LIBRE | G15: AM | H15: AM | I15: AM | J15: AM | K15: AM | L15: LIBRE | M15: LIBRE | O15: AM | P15: AM | Q15: AM | R15: AM | S15: AM | T15: LIBRE | U15: LIBRE | W15: FULL | X15: FULL | Y15: FULL | Z15: LIBRE | AA15: FULL | AB15: FULL | AC15: LIBRE | AE15: LIBRE | AF15: FULL | AG15: FULL | AH15: FULL | AI15: LIBRE | AJ15: FULL | AK15: FULL | AM15: FULL | AN15: FULL | AO15: FULL | AP15: LIBRE | AQ15: FULL | AR15: FULL | AS15: LIBRE | AU15: LIBRE | AV15: FULL | AW15: FULL | AX15: FULL | AY15: LIBRE | AZ15: FULL | BA15: FULL | BC15: FULL | BD15: FULL | BE15: FULL | BF15: LIBRE | BG15: FULL | BH15: FULL | BI15: LIBRE | BK15: LIBRE | BL15: FULL | BM15: FULL | BN15: FULL | BO15: LIBRE | BP15: FULL | BQ15: FULL | BS15: FULL | BT15: FULL
A16: Local 95 | B16: Teresa | W16: LIBRE | X16: FULL | Y16: FULL | Z16: FULL | AA16: LIBRE | AB16: FULL | AC16: FULL | AE16: FULL | AF16: FULL | AG16: FULL | AH16: LIBRE | AI16: FULL | AJ16: FULL | AK16: LIBRE | AM16: LIBRE | AN16: FULL | AO16: FULL | AP16: FULL | AQ16: LIBRE | AR16: FULL | AS16: FULL | AU16: FULL | AV16: FULL | AW16: FULL | AX16: LIBRE | AY16: FULL | AZ16: FULL | BA16: LIBRE | BC16: LIBRE | BD16: FULL | BE16: FULL | BF16: FULL | BG16: LIBRE | BH16: FULL | BI16: FULL | BK16: FULL | BL16: FULL | BM16: FULL | BN16: LIBRE | BO16: FULL | BP16: FULL | BQ16: LIBRE | BS16: LIBRE | BT16: FULL

Sheet CItaciones FH
B1: CITACIONES MAYO 2026 | FH_ESTIVALES | DÍAS 01 AL 26
B2: Local | C2: Patente | D2: Total días activos | E2: Vie 01 | F2: Sáb 02 | G2: Dom 03 | H2: Lun 04 | I2: Mar 05 | J2: Mié 06 | K2: Jue 07 | L2: Vie 08 | M2: Sáb 09 | N2: Dom 10 | O2: Lun 11 | P2: Mar 12 | Q2: Mié 13 | R2: Jue 14 | S2: Vie 15 | T2: Sáb 16 | U2: Dom 17 | V2: Lun 18 | W2: Mar 19 | X2: Mié 20 | Y2: Jue 21 | Z2: Vie 22 | AA2: Sáb 23 | AB2: Dom 24 | AC2: Lun 25 | AD2: Mar 26
A3: Activo | B3: L58 | C3: SYSS70 | D3: 14 | F3: X | I3: X | K3: X | L3: X | O3: X | Q3: X | R3: X | T3: X | U3: X | V3: X | X3: X | Y3: X | AC3: X | AD3: X
A4: Activo | B4: L58 | C4: PPWY63 | D4: 11 | F4: X | J4: X | K4: X | M4: X | P4: X | Q4: X | U4: X | X4: X | Y4: X | Z4: X | AB4: X
A5: Activo | B5: L58 | C5: SRYH57 | D5: 10 | H5: X | I5: X | L5: X | R5: X | S5: X | W5: X | Y5: X | Z5: X | AB5: X | AD5: X
A6: Activo | B6: L58 | C6: STWR86 | D6: 10 | F6: X | G6: X | H6: X | J6: X | M6: X | R6: X | S6: X | W6: X | X6: X | Z6: X
A7: Activo | B7: L58 | C7: TPXY11 | D7: 7 | F7: X | H7: X | T7: X | V7: X | Y7: X | AA7: X | AC7: X
A8: Activo | B8: L58 | C8: VHSW61 | D8: 6 | N8: X | O8: X | R8: X | Y8: X | Z8: X | AA8: X
A9: Activo | B9: L58 | C9: TVZC13 | D9: 5 | G9: X | I9: X | J9: X | N9: X | P9: X
A10: Panne | B10: L58 | C10: DLCB16 | D10: 2 | G10: X | X10: X
A11: Activo | B11: L58(l983) | C11: SVLY73 | D11: 0
A12: Panne | B12: L58(l983) | C12: TSTP28 | D12: 0
A13: Activo | B13: L94 | C13: TRYL78 | D13: 15 | F13: X | G13: X | H13: X | I13: X | J13: X | K13: X | L13: X | M13: X | R13: X | S13: X | U13: X | W13: X | Y13: X | AA13: X | AC13: X
A14: Activo | B14: L94 | C14: VJPH80 | D14: 15 | K14: X | L14: X | M14: X | N14: X | O14: X | P14: X | Q14: X | R14: X | T14: X | U14: X | V14: X | X14: X | Z14: X | AB14: X | AD14: X
A15: Activo | B15: L94 | C15: VJWK44 | D15: 15 | F15: X | G15: X | H15: X | I15: X | J15: X | K15: X | L15: X | N15: X | O15: X | Q15: X | T15: X | U15: X | W15: X | Z15: X | AD15: X
A16: Activo | B16: L94 | C16: VGWW22 | D16: 13 | F16: X | G16: X | H16: X | I16: X | J16: X | L16: X | O16: X | P16: X | X16: X | Y16: X | AA16: X | AB16: X | AC16: X
A17: Activo | B17: L94 | C17: LRXY26 | D17: 8 | J17: X | K17: X | M17: X | S17: X | W17: X | X17: X | Y17: X | Z17: X
A18: Panne | B18: L94 | C18: PGHD38 | D18: 0
A19: Activo | B19: L94 | C19: VJRT63
A20: Activo | B20: L98 | C20: KSXP45 | D20: 13 | F20: X | G20: X | I20: X | J20: X | K20: X | M20: X | P20: X | R20: X | S20: X | T20: X | V20: X | Z20: X | AD20: X
A21: Activo | B21: L98 | C21: RTTR83 | D21: 13 | F21: X | G21: X | I21: X | J21: X | K21: X | L21: X | P21: X | R21: X | T21: X | W21: X | Y21: X | AA21: X | AD21: X
A22: Activo | B22: L98 | C22: SDYY74 | D22: 12 | F22: X | G22: X | H22: X | M22: X | N22: X | O22: X | P22: X | Q22: X | U22: X | W22: X | Y22: X | AC22: X
A23: Activo | B23: L98 | C23: TRPP43 | D23: 12 | F23: X | G23: X | H23: X | I23: X | J23: X | N23: X | O23: X | S23: X | T23: X | V23: X | X23: X | AC23: X
A24: Activo | B24: L98 | C24: VKJF15 | D24: 12 | F24: X | G24: X | H24: X | I24: X | K24: X | M24: X | N24: X | R24: X | T24: X | U24: X | W24: X | AB24: X
A25: Falta piso(Revisar) | B25: L98 | C25: RDLW17
A26: Activo | B26: L98 | C26: PCFZ21
A27: Activo | B27: L98 | C27: VDSH17
A28: Activo | B28: L98 | C28: PRFC70 | D28: 10 | G28: X | H28: X | I28: X | L28: X | M28: X | Q28: X | R28: X | U28: X | X28: X | AA28: X
A29: Activo | B29: L98 | C29: RBYF40 | D29: 10 | F29: X | G29: X | H29: X | I29: X | L29: X | O29: X | Q29: X | T29: X | W29: X | Z29: X
A30: Activo | B30: L98 | C30: RPWK21 | D30: 10 | F30: X | H30: X | I30: X | J30: X | L30: X | M30: X | S30: X | X30: X | AA30: X | AB30: X
A31: Activo | B31: L98 | C31: SKXW43 | D31: 10 | F31: X | J31: X | K31: X | M31: X | N31: X | R31: X | S31: X | T31: X | W31: X | Y31: X
A32: Activo | B32: L98 | C32: TJDR58 | D32: 10 | I32: X | K32: X | M32: X | N32: X | O32: X | P32: X | U32: X | V32: X | AA32: X | AB32: X
A33: Activo | B33: L98 | C33: LSVH23 | D33: 8 | F33: X | H33: X | L33: X | P33: X | Q33: X | V33: X | AA33: X | AB33: X
A34: Activo | B34: L98 | C34: PCJZ43 | D34: 3 | F34: X | G34: X | I34: X
A35: Activo | B35: L99 | C35: LHZW29 | D35: 11 | F35: X | G35: X | H35: X | I35: X | J35: X | K35: X | L35: X | M35: X | N35: X | P35: X | Q35: X
A36: Activo | B36: L99 | C36: VJWK40 | D36: 11 | F36: X | G36: X | H36: X | I36: X | J36: X | K36: X | L36: X | M36: X | N36: X | O36: X | Q36: X
A37: Activo | B37: L99 | C37: VJWK39 | D37: 10 | G37: X | H37: X | I37: X | J37: X | K37: X | L37: X | M37: X | N37: X | O37: X | P37: X
A38: Activo | B38: L99 | C38: JTYF43 | D38: 7 | J38: X | K38: X | L38: X | M38: X | N38: X | P38: X | Q38: X
A39: Activo | B39: L99 | C39: LLXD43 | D39: 5 | F39: X | G39: X | H39: X | I39: X | O39: X
A40: Parte 29/05 | B40: L99 | C40: VJPH72 | D40: 0
...

Sheet Copia de CItaciones FLD 
A1: CITACIONES MAYO 2026 | MM | DÍAS 01 AL 26
A2: Local | B2: Patente | C2: Total días activos | D2: Vie 01 | E2: Sáb 02 | F2: Dom 03 | G2: Lun 04 | H2: Mar 05 | I2: Mié 06 | J2: Jue 07 | K2: Vie 08 | L2: Sáb 09 | M2: Dom 10 | N2: Lun 11 | O2: Mar 12 | P2: Mié 13 | Q2: Jue 14 | R2: Vie 15 | S2: Sáb 16 | T2: Dom 17 | U2: Lun 18 | V2: Mar 19 | W2: Mié 20 | X2: Jue 21 | Y2: Vie 22 | Z2: Sáb 23 | AA2: Dom 24 | AB2: Lun 25 | AC2: Mar 26
A3: L45 | B3: JCRZ41 | C3: 17 | F3: X | G3: X | H3: X | I3: X | J3: X | K3: X | L3: X | N3: X | O3: X | P3: X | Q3: X | R3: X | S3: X | V3: X | W3: X | Y3: X | AC3: X
A4: L45 | B4: PPXL56 | C4: 17 | E4: X | F4: X | G4: X | H4: X | I4: X | J4: X | K4: X | L4: X | N4: X | P4: X | Q4: X | U4: X | W4: X | Y4: X | Z4: X | AB4: X | AC4: X
A5: L45 | B5: PZLX49 | C5: 17 | F5: X | G5: X | H5: X | I5: X | J5: X | K5: X | L5: X | O5: X | Q5: X | R5: X | S5: X | T5: X | V5: X | X5: X | Z5: X | AA5: X | AB5: X
A6: L45 | B6: HDJW94 | C6: 16 | E6: X | F6: X | G6: X | I6: X | J6: X | K6: X | L6: X | P6: X | Q6: X | S6: X | T6: X | V6: X | X6: X | Z6: X | AA6: X | AB6: X
A7: L45 | B7: RRSX45 | C7: 15 | E7: X | F7: X | G7: X | I7: X | J7: X | K7: X | L7: X | M7: X | S7: X | T7: X | U7: X | W7: X | X7: X | Z7: X | AA7: X
A8: L45 | B8: HVDK36 | C8: 13 | F8: X | G8: X | H8: X | I8: X | J8: X | P8: X | R8: X | U8: X | W8: X | X8: X | Z8: X | AB8: X | AC8: X
A9: L45 | B9: PSCW71 | C9: 13 | K9: X | L9: X | M9: X | N9: X | O9: X | P9: X | S9: X | T9: X | U9: X | W9: X | Y9: X | Z9: X | AB9: X
A10: L45 | B10: KBGZ36 | C10: 12 | E10: X | F10: X | G10: X | O10: X | P10: X | Q10: X | R10: X | S10: X | T10: X | V10: X | Z10: X | AB10: X
A11: L45 | B11: RRLF86 | C11: 12 | H11: X | I11: X | J11: X | K11: X | L11: X | P11: X | Q11: X | R11: X | U11: X | W11: X | Y11: X | AC11: X
A12: L45 | B12: LJTV50 | C12: 10 | P12: X | Q12: X | R12: X | S12: X | T12: X | V12: X | X12: X | Y12: X | Z12: X | AC12: X
A13: L45 | B13: RBSD26 | C13: 10 | E13: X | G13: X | H13: X | I13: X | J13: X | N13: X | O13: X | P13: X | R13: X | U13: X
A14: L45 | B14: KCWL95 | C14: 9 | E14: X | H14: X | J14: X | K14: X | L14: X | W14: X | X14: X | Z14: X | AA14: X
A15: L58 | B15: SCWZ56 | C15: 16 | F15: X | G15: X | H15: X | J15: X | L15: X | M15: X | N15: X | Q15: X | R15: X | S15: X | T15: X | V15: X | W15: X | X15: X | Z15: X | AB15: X
A16: L58 | B16: JLPZ25 | C16: 15 | G16: X | H16: X | J16: X | K16: X | L16: X | N16: X | O16: X | P16: X | Q16: X | U16: X | V16: X | W16: X | X16: X | Z16: X | AB16: X
A17: L58 | B17: LZGV53 | C17: 15 | E17: X | F17: X | G17: X | K17: X | L17: X | M17: X | N17: X | O17: X | Q17: X | T17: X | U17: X | Y17: X | AA17: X | AB17: X | AC17: X
A18: L58 | B18: RDKS16 | C18: 14 | G18: X | H18: X | I18: X | J18: X | K18: X | P18: X | Q18: X | R18: X | T18: X | U18: X | X18: X | Y18: X | AA18: X | AC18: X
A19: L58 | B19: GLBZ25 | C19: 12 | E19: X | J19: X | K19: X | L19: X | O19: X | P19: X | Q19: X | S19: X | V19: X | W19: X | Y19: X | AC19: X
A20: L58 | B20: JKDP45 | C20: 11 | F20: X | H20: X | I20: X | L20: X | N20: X | R20: X | S20: X | U20: X | W20: X | Z20: X | AB20: X
A21: L58 | B21: JVHZ54 | C21: 11 | E21: X | G21: X | I21: X | M21: X | P21: X | R21: X | S21: X | W21: X | Y21: X | AA21: X | AC21: X
A22: L58 | B22: KBGZ82 | C22: 9 | E22: X | F22: X | H22: X | K22: X | M22: X | N22: X | O22: X | X22: X | AA22: X
A23: L58 | B23: JTRH38 | C23: 6 | O23: X | P23: X | T23: X | V23: X | Y23: X | AC23: X
A24: L58 | B24: LYVP54 | C24: 2 | X24: X | Z24: X
A25: L58 | B25: KTGT79 | C25: 0
A26: L95 | B26: FJTT27 | C26: 13 | E26: X | F26: X | H26: X | I26: X | J26: X | K26: X | O26: X | Q26: X | R26: X | V26: X | X26: X | Z26: X | AC26: X
A27: L95 | B27: KZPY29 | C27: 13 | E27: X | F27: X | J27: X | K27: X | L27: X | M27: X | O27: X | P27: X | Q27: X | U27: X | V27: X | X27: X | AB27: X
A28: L95 | B28: RTXS54 | C28: 13 | E28: X | F28: X | G28: X | I28: X | J28: X | K28: X | N28: X | Q28: X | R28: X | S28: X | U28: X | AA28: X | AC28: X
A29: L95 | B29: SJCY30 | C29: 12 | F29: X | G29: X | H29: X | I29: X | N29: X | O29: X | Q29: X | T29: X | V29: X | W29: X | Z29: X | AC29: X
A30: L95 | B30: VDVB53 | C30: 12 | F30: X | I30: X | J30: X | L30: X | N30: X | P30: X | Q30: X | S30: X | W30: X | X30: X | AB30: X | AC30: X
A31: L95 | B31: GYKP40 | C31: 11 | E31: X | G31: X | K31: X | L31: X | Q31: X | R31: X | S31: X | W31: X | Y31: X | Z31: X | AB31: X
A32: L95 | B32: PDZS86 | C32: 11 | I32: X | J32: X | K32: X | N32: X | P32: X | Q32: X | U32: X | V32: X | X32: X | Y32: X | AB32: X
A33: L95 | B33: JWDH77 | C33: 10 | G33: X | I33: X | J33: X | L33: X | P33: X | Q33: X | R33: X | V33: X | Y33: X | AB33: X
A34: L95 | B34: TPVK74 | C34: 10 | H34: X | J34: X | K34: X | O34: X | Q34: X | R34: X | V34: X | Y34: X | Z34: X | AB34: X
A35: L95 | B35: RYTC41 | C35: 9 | G35: X | H35: X | I35: X | J35: X | K35: X | S35: X | T35: X | X35: X | AC35: X
A36: L98 | B36: PRLG54 | C36: 15 | E36: X | F36: X | G36: X | H36: X | I36: X | J36: X | L36: X | M36: X | O36: X | P36: X | Q36: X | T36: X | V36: X | Y36: X | AB36: X
A37: L98 | B37: KXKJ82 | C37: 14 | E37: X | G37: X | H37: X | J37: X | K37: X | M37: X | N37: X | P37: X | R37: X | S37: X | W37: X | Y37: X | AB37: X | AC37: X
A38: L98 | B38: RCLZ94 | C38: 13 | E38: X | F38: X | H38: X | I38: X | L38: X | N38: X | Q38: X | S38: X | U38: X | X38: X | Z38: X | AA38: X | AC38: X
A39: L98 | B39: JWXL72 | C39: 12 | G39: X | H39: X | I39: X | J39: X | K39: X | N39: X | O39: X | R39: X | U39: X | V39: X | AA39: X | AB39: X
A40: L98 | B40: LTXC53 | C40: 8 | I40: X | J40: X | L40: X | N40: X | O40: X | T40: X | V40: X | W40: X
...

Sheet Hoja 27
A1: Local | B1: Identificador | C1: Patente | D1: Status | E1: Resolución Sanitaria | F1: CORREO | G1: RUT | H1: NOMBRE | I1: TELEFONO | J1: Llamada/contacto
A2: L120 (Temuco) | B2: HDVSHZRX80 | C2: HZRX80 | D2: Activa | E2: Si cuenta con RS | F2: christianscheel@transcheel.cl | G2: 79850340-5 | H2: Transcheel Limitada | I2: 978520324 | J2: RS LISTA
A3: L120 (Temuco) | B3: HDVSKCHJ51 | C3: KCHJ51 | D3: Activa | E3: Si cuenta con RS | F3: cristian.contreras.reyes@gmail.com | G3: 19477117-7 | H3: Benjamín Contreras espinoza | I3: 973891360 | J3: RS LISTA
A4: L120 (Temuco) | B4: HDVSKKJZ64 | C4: KKJZ64 | D4: Activa | E4: Si cuenta con RS | F4: salvadorsilva.syb@gmail.com | G4: 17581873-1 | H4: Salvador fernando silva stuardo | I4: 957921240 | J4: RS LISTA
A5: L120 (Temuco) | B5: HDVSKYSJ80 | C5: KYSJ80 | D5: Activa | E5: Si cuenta con RS | F5: salvadorsilva.syb@gmail.com | G5: 17581873-1 | H5: Salvador fernando silva stuardo | I5: 957921240 | J5: RS LISTA
A6: L120 (Temuco) | B6: HDVSKZZY17 | C6: KZZY17 | D6: Activa | E6: Si cuenta con RS | F6: Jlqb1979@gmail.com | G6: 76935957-5 | H6: Pasajes Encominedas Jessica Cofre Eirl | I6: 930768805 | J6: RS LISTA
A7: L120 (Temuco) | B7: HDVSLHVR22 | C7: LHVR22 | D7: Activa | E7: Si cuenta con RS | F7: yonathanuribe98@gmail.com | G7: 19810237-7 | H7: Yonathan Eduardo Uribe valencia | I7: 999812071 | J7: RS LISTA
A8: L120 (Temuco) | B8: HDVSPGJL89 | C8: PGJL89 | D8: Activa | E8: Si cuenta con RS | F8: salvadorsilva.syb@gmail.com | G8: 17581873-1 | H8: Salvador fernando silva stuardo | I8: 957921240 | J8: RS LISTA
A9: L120 (Temuco) | B9: HDVSRXTL44 | C9: RXTL44 | D9: Activa | E9: Si cuenta con RS | F9: desarmadurialabranzatemucospa@gmail.com | G9: 21356499-4 | H9: DANIEL ALEJANDRO CANCINO BUSTAMANTE | I9: 966053344 | J9: RS LISTA
A10: L120 (Temuco) | B10: HDVSRYJR47 | C10: RYJR47 | D10: Activa | E10: Si cuenta con RS | F10: quirozdiego199530@gmail.com | G10: 19195970-1 | H10: Diego Alfonso Quiroz Alvial | I10: 985808473 | J10: RS LISTA
A11: L120 (Temuco) | B11: HDVSTKWX57 | C11: TKWX57 | D11: Activa | E11: No se encuentra resolución sanitaria | F11: empresabusesdelsur@gmail.com | G11: 14215495-1 | H11: Gerardo Andrés Jara Fernández | I11: 56985635643 | J11: En proceso de obtener, consultará en oficinas cuanto es el proceso
A12: L120 (Temuco) | B12: HDVSTRYL82 | C12: TRYL82 | D12: Activa | E12: No se encuentra documentación | F12: dobblevia1@gmail.com | G12: 15952434-5 | H12: Romina De Lourdes Vasquez Catalan | I12: 944416112 | J12: PPU DE VS
A13: L120 (Temuco) | B13: HDVSTSCT51 | C13: TSCT51 | D13: Activa | E13: No se encuentra documentación | F13: dobblevia1@gmail.com | G13: 15952434-5 | H13: Romina De Lourdes Vasquez Catalan | I13: 944416112 | J13: PPU DE VS
... A63: 99 (Puerto Montt) | B63: HDVSLLXD43 | C63: LLXD43 | D63: Activa | E63: No se encuentra resolución sanitaria | F63: JESUS.COYOPAE@GMAIL.COM | G63: 17299443-1 | H63: JESÚS JAVIER COYOPAE PACHECO | I63: 973322624 | J63: Está en tramite con a documentacióon de ambos vehiculos

Sheet Telemetria
A1: Local | B1: Usuario BT | C1: Patente | D1: Estatus | E1: Observacion
A2: 120 | B2: HDVSHKSV64 | C2: =RIGHT(B2,6) -> HKSV64 | D2: Instalacion Lista | E2: Planificar /Pendiente | F2: Ok
A3: 120 | B3: HDVSHZRX80 | C3: =RIGHT(B3,6) -> HZRX80 | D3: Instalacion Lista | F3: Ok
A4: 120 | B4: HDVSKCHJ51 | C4: =RIGHT(B4,6) -> KCHJ51 | D4: Instalacion Lista | F4: Ok
A5: 120 | B5: HDVSKJJX80 | C5: =RIGHT(B5,6) -> KJJX80 | D5: Instalacion Lista | E5: Pasa a cobro | F5: Ok
A6: 120 | B6: HDVSKKJZ64 | C6: =RIGHT(B6,6) -> KKJZ64 | D6: Instalacion Lista | F6: Ok
A7: 120 | B7: HDVSKTZY10 | C7: =RIGHT(B7,6) -> KTZY10 | D7: Instalacion Lista | E7: Pasa a cobro | F7: Ok
A8: 120 | B8: HDVSKTZY11 | C8: =RIGHT(B8,6) -> KTZY11 | D8: Pendiente Instalacion | E8: No aplica | F8: No
A9: 120 | B9: HDVSKYSJ80 | C9: =RIGHT(B9,6) -> KYSJ80 | D9: Instalacion Lista | F9: Ok
A10: 120 | B10: HDVSPGJL89 | C10: =RIGHT(B10,6) -> PGJL89 | D10: Instalacion Lista
A11: 120 | B11: HDVSKZZY17 | C11: =RIGHT(B11,6) -> KZZY17 | D11: Instalacion Lista | F11: Ok
A12: 120 | B12: HDVSLFZC21 | C12: =RIGHT(B12,6) -> LFZC21 | D12: Instalacion Lista | E12: Retirada | F12: Ok
A13: 120 | B13: HDVSLHVR22 | C13: =RIGHT(B13,6) -> LHVR22 | D13: Instalacion Lista | E13: Planificar /Pendiente | F13: Ok
A14: 120 | B14: HDVSRGVV55 | C14: =RIGHT(B14,6) -> RGVV55 | D14: Instalacion Lista | E14: Retirada | F14: Ok
A15: 120 | B15: HDVSRXTL44 | C15: =RIGHT(B15,6) -> RXTL44 | D15: Instalacion Lista | F15: Ok
A16: 120 | B16: HDVSRYJR47 | C16: =RIGHT(B16,6) -> RYJR47 | D16: Instalacion Lista | F16: No
A17: 120 | B17: HDVSTKWX57 | C17: =RIGHT(B17,6) -> TKWX57 | D17: Instalacion Lista | F17: Ok
A18: 120 | B18: HDVSTRYL82 | C18: =RIGHT(B18,6) -> TRYL82 | D18: Instalacion Lista | F18: Ok | I18: 120 | J18: OK
A19: 120 | B19: HDVSTSCT51 | C19: =RIGHT(B19,6) -> TSCT51 | D19: Instalacion Lista | F19: Ok | I19: 618 | J19: REVISAR 87
B20: HDVSPGJL89 | C20: =RIGHT(B20,6) -> PGJL89 | D20: Pendiente Instalacion
A21: 120 | B21: HDVSTZCH26 | C21: =RIGHT(B21,6) -> TZCH26 | D21: Instalacion Lista | F21: Ok | I21: 99 | J21: OK
A22: 121 | B22: HDVSCJJY36 | C22: =RIGHT(B22,6) -> CJJY36 | D22: Instalacion Lista | F22: Ok | I22: 657 | J22: OK
A23: 121 | B23: HDVSRHXG50 | C23: =RIGHT(B23,6) -> RHXG50 | D23: Instalacion Lista | F23: Ok | I23: 98 | J23: OK
A24: 121 | B24: HDVSVLHB59 | C24: =RIGHT(B24,6) -> VLHB59 | D24: Instalacion Lista | F24: Ok | I24: 94 | J24: REVISAR 2 PPU
A25: 121 | B25: HDVSGW69 | C25: VSGW69 | D25: Instalacion Lista | F25: OK
A26: 121 | B26: HDVSRHWY99 | C26: =RIGHT(B26,6) -> RHWY99 | D26: Instalacion Lista | F26: Ok
A27: 121 | B27: HDVSPTGD93 | C27: =RIGHT(B27,6) -> PTGD93 | D27: Instalacion Lista | F27: Ok | J27: PLYC18
A28: 121 | B28: HDVSRPGK29 | C28: =RIGHT(B28,6) -> RPGK29 | D28: Instalacion Lista | F28: Ok
A29: 121 | B29: HDVSSBTV68 | C29: =RIGHT(B29,6) -> SBTV68 | D29: Instalacion Lista | F29: Ok
A30: 121 | B30: HDVSPSLP82 | C30: =RIGHT(B30,6) -> PSLP82 | D30: Instalacion Lista | F30: Ok
A31: 121 | B31: HDVSVDZC94 | C31: =RIGHT(B31,6) -> VDZC94 | D31: Instalacion Lista | F31: Ok
A32: 121 | B32: HDVSTYWH80 | C32: =RIGHT(B32,6) -> TYWH80 | D32: Instalacion Lista | F32: No aparece
A33: 121 | B33: HDVSRVPT55 | C33: =RIGHT(B33,6) -> RVPT55 | D33: Pendiente Instalacion | E33: Pendiente | F33: No
A34: 58 | B34: HDVSCJYL78 | C34: =RIGHT(B34,6) -> CJYL78 | D34: Pendiente Instalacion | E34: No aplica | F34: No
A35: 58 | B35: HDVSDLCB16 | C35: =RIGHT(B35,6) -> DLCB16 | D35: Instalacion Lista | F35: Ok
A36: 58 | B36: HDVSJPVT35 | C36: =RIGHT(B36,6) -> JPVT35 | D36: Instalacion Lista | E36: Retirada | F36: Ok | G36: No se presenta (TPXY11) | H36: 46088
